Workbook

Sheet 說明
A1: 作者本人判定表（一致性分析：人工評估者）
A2: 1. 依 docs/spec/inspection-spec-v1.md（檢驗規範 v1）判定 experiment/samples/ 中的 40 張樣本影像。
A3: 2. 先填「第1輪」，隔天再填「第2輪」（兩輪順序已打亂且不同），第2輪時不要回看第1輪。
A4: 3. 每張樣本一列：缺陷代碼、區域、量測 (µm，5 µm/px)、判定（下拉選 Pass／Warning／Fail）。無缺陷請填「無」並判 Pass。
A5: 4. 「重複性計算」工作表會自動計算本人重複性、對標準答案一致率、漏判率、誤判率、人工複判率。
A6: 5. 「標準答案」工作表已隱藏；兩輪都填完後再取消隱藏（右鍵工作表標籤 → 取消隱藏）。

Sheet 第1輪
A1: 序 | B1: 樣本 | C1: 缺陷代碼（無／CHP／CRK／SCR／CON，多個以 ; 分隔） | D1: 區域（core／peripheral） | E1: 量測 (µm) | F1: 判定 | G1: 備註
A2: 1 | B2: S19 | C2: CON;CON | D2: core | E2: 20;30 | F2: Warning | G2: 有兩顆
A3: 2 | B3: S08 | C3: CHP | D3: peripheral | E3: 20 | F3: Fail
A4: 3 | B4: S24 | C4: CHP | D4: peripheral | E4: 15 | F4: Fail
A5: 4 | B5: S17 | C5: 無 | F5: Pass
A6: 5 | B6: S23 | C6: CHP | D6: peripheral | E6: 105 | F6: Fail
A7: 6 | B7: S22 | C7: 無 | F7: Pass
A8: 7 | B8: S07 | C8: 無 | F8: Pass
A9: 8 | B9: S11 | C9: 無 | F9: Pass
A10: 9 | B10: S25 | C10: SCR | D10: core | E10: 452 | F10: Warning
A11: 10 | B11: S27 | C11: 無 | F11: Pass
A12: 11 | B12: S34 | C12: CRK | D12: core | E12: 230 | F12: Fail
A13: 12 | B13: S16 | C13: 無 | F13: Pass
A14: 13 | B14: S38 | C14: CHP | D14: peripheral | E14: 40 | F14: Fail
A15: 14 | B15: S09 | C15: 無 | F15: Pass
A16: 15 | B16: S14 | C16: SCR | D16: core | E16: 45 | F16: Warning
A17: 16 | B17: S01 | C17: SCR | D17: core | E17: 150 | F17: Warning
A18: 17 | B18: S28 | C18: 無 | F18: Pass
A19: 18 | B19: S37 | C19: SCR | D19: core | E19: 250 | F19: Warning
A20: 19 | B20: S35 | C20: CON | D20: core | E20: 30 | F20: Warning
A21: 20 | B21: S02 | C21: 無 | F21: Pass
A22: 21 | B22: S32 | C22: CON | D22: core | E22: 15 | F22: Warning
A23: 22 | B23: S18 | C23: CHP | D23: peripheral | E23: 155
A24: 23 | B24: S03 | C24: 無 | F24: Pass
A25: 24 | B25: S05 | C25: 無 | F25: Pass
A26: 25 | B26: S10 | C26: 無 | F26: Pass
A27: 26 | B27: S15 | C27: 無 | F27: Pass
A28: 27 | B28: S04 | C28: CON;CON;CON | D28: core | E28: 20;30;30 | F28: Fail | G28: 3顆
A29: 28 | B29: S06 | C29: 無 | F29: Pass
A30: 29 | B30: S26 | C30: 無 | F30: Pass
A31: 30 | B31: S20 | C31: CON | D31: core | E31: 75 | F31: Warning
A32: 31 | B32: S21 | C32: 無 | F32: Pass
A33: 32 | B33: S31 | C33: CON | D33: peripheral | E33: 25 | F33: Warning
A34: 33 | B34: S39 | C34: 無 | F34: Pass
A35: 34 | B35: S12 | C35: 無 | F35: Pass
A36: 35 | B36: S13 | C36: 無 | F36: Pass
A37: 36 | B37: S33 | C37: CHP | D37: peripheral | E37: 20 | F37: Warning
A38: 37 | B38: S40 | C38: 無 | F38: Pass
A39: 38 | B39: S30 | C39: 無 | F39: Pass
A40: 39 | B40: S36 | C40: 無 | F40: Pass
...

Sheet 第2輪
A1: 序 | B1: 樣本 | C1: 缺陷代碼（無／CHP／CRK／SCR／CON，多個以 ; 分隔） | D1: 區域（core／peripheral） | E1: 量測 (µm) | F1: 判定 | G1: 備註
A2: 1 | B2: S37 | C2: SCR | E2: 110 | F2: Warning
A3: 2 | B3: S07 | C3: 無 | F3: Pass
A4: 3 | B4: S32 | C4: CON | D4: core | E4: 20 | F4: Warning
A5: 4 | B5: S13 | C5: SCR | D5: peripheral | E5: 400 | F5: Warning
A6: 5 | B6: S35 | C6: CON | D6: core | E6: 25 | F6: Warning
A7: 6 | B7: S39 | C7: 無 | F7: Pass
A8: 7 | B8: S05 | C8: 無 | F8: Pass
A9: 8 | B9: S27 | C9: 無 | F9: Pass
A10: 9 | B10: S28 | C10: 無 | F10: Pass
A11: 10 | B11: S36 | C11: 無 | F11: Pass
A12: 11 | B12: S26 | C12: 無 | F12: Pass
A13: 12 | B13: S17 | C13: 無 | F13: Pass
A14: 13 | B14: S25 | C14: SCR | D14: peripheral | E14: 452 | F14: Warning
A15: 14 | B15: S03 | C15: 無 | F15: Pass
A16: 15 | B16: S04 | C16: CON;CON;CON | D16: core | E16: 25;30;30 | F16: Fail
A17: 16 | B17: S34 | C17: CRK | F17: Fail
A18: 17 | B18: S10 | C18: 無 | F18: Pass
A19: 18 | B19: S31 | C19: 無 | F19: Pass
A20: 19 | B20: S21 | C20: 無 | F20: Pass
A21: 20 | B21: S01 | C21: SCR | D21: peripheral | E21: 150 | F21: Warning
A22: 21 | B22: S19 | C22: CON;CON | D22: core | E22: 30;15 | F22: Warning
A23: 22 | B23: S30 | C23: 無 | F23: Pass
A24: 23 | B24: S14 | C24: SCR | D24: core | E24: 55 | F24: Warning
A25: 24 | B25: S24 | C25: 無 | F25: Pass
A26: 25 | B26: S22 | C26: 無 | F26: Pass
A27: 26 | B27: S18 | C27: CHP | D27: peripheral | E27: 140 | F27: Fail
A28: 27 | B28: S33 | C28: CHP | D28: peripheral | E28: 15 | F28: Fail
A29: 28 | B29: S20 | C29: CON | D29: core | E29: 50 | F29: Warning
A30: 29 | B30: S11 | C30: 無 | F30: Pass
A31: 30 | B31: S38 | C31: CHP | D31: peripheral | E31: 25 | F31: Fail
A32: 31 | B32: S40 | C32: CON | D32: peripheral | E32: 25 | F32: Warning
A33: 32 | B33: S15 | C33: 無 | F33: Pass
A34: 33 | B34: S06 | C34: 無 | F34: Pass
A35: 34 | B35: S23 | C35: CHP | D35: peripheral | E35: 90 | F35: Fail
A36: 35 | B36: S08 | C36: CHP | D36: peripheral | E36: 10 | F36: Fail
A37: 36 | B37: S12 | C37: 無 | F37: Pass
A38: 37 | B38: S29 | C38: 無 | F38: Pass
A39: 38 | B39: S02 | C39: 無 | F39: Pass
A40: 39 | B40: S16 | C40: 無 | F40: Pass
...

Sheet 標準答案
A1: 樣本 | B1: 標準答案判定 | C1: 標準答案缺陷
A2: S01 | B2: Warning | C2: SCR core 150.0µm
A3: S02 | B3: Pass | C3: 無
A4: S03 | B4: Pass | C4: SCR peripheral 250.0µm
A5: S04 | B5: Fail | C5: CON core 25µm; CON core 30µm; CON core 35µm
A6: S05 | B6: Warning | C6: CON peripheral 60µm
A7: S06 | B7: Pass | C7: 無
A8: S07 | B8: Pass | C8: 無
A9: S08 | B9: Warning | C9: CHP peripheral 25µm
A10: S09 | B10: Pass | C10: 無
A11: S10 | B11: Pass | C11: CON core 15µm; CHP peripheral 6µm
A12: S11 | B12: Pass | C12: 無
... A41: S40 | B41: Pass | C41: 無

Sheet 重複性計算
A1: 樣本 | B1: 第1輪判定 | C1: 第2輪判定 | D1: 兩輪一致 (1/0) | E1: 標準答案 | F1: 第1輪對 (1/0) | G1: 第2輪對 (1/0)
A2: S01 | B2: {=IFERROR(IF(INDEX('第1輪'!$F$2:$F$41,MATCH(A2,'第1輪'!$B$2:$B$41,0))="","",INDEX('第1輪'!$F$2:$F$41,MATCH(A2,'第1輪'!$B$2:$B$41,0))),"")} -> Warning | C2: {=IFERROR(IF(INDEX('第2輪'!$F$2:$F$41,MATCH(A2,'第2輪'!$B$2:$B$41,0))="","",INDEX('第2輪'!$F$2:$F$41,MATCH(A2,'第2輪'!$B$2:$B$41,0))),"")} -> Warning | D2: =IF(OR(B2="",C2=""),"",IF(B2=C2,1,0)) -> 1 | E2: {=IFERROR(INDEX('標準答案'!$B$2:$B$41,MATCH(A2,'標準答案'!$A$2:$A$41,0)),"")} -> Warning | F2: =IF(B2="","",IF(B2=E2,1,0)) -> 1 | G2: =IF(C2="","",IF(C2=E2,1,0)) -> 1
A3: S02 | B3: {=IFERROR(IF(INDEX('第1輪'!$F$2:$F$41,MATCH(A3,'第1輪'!$B$2:$B$41,0))="","",INDEX('第1輪'!$F$2:$F$41,MATCH(A3,'第1輪'!$B$2:$B$41,0))),"")} -> Pass | C3: {=IFERROR(IF(INDEX('第2輪'!$F$2:$F$41,MATCH(A3,'第2輪'!$B$2:$B$41,0))="","",INDEX('第2輪'!$F$2:$F$41,MATCH(A3,'第2輪'!$B$2:$B$41,0))),"")} -> Pass | D3: =IF(OR(B3="",C3=""),"",IF(B3=C3,1,0)) -> 1 | E3: {=IFERROR(INDEX('標準答案'!$B$2:$B$41,MATCH(A3,'標準答案'!$A$2:$A$41,0)),"")} -> Pass | F3: =IF(B3="","",IF(B3=E3,1,0)) -> 1 | G3: =IF(C3="","",IF(C3=E3,1,0)) -> 1
A4: S03 | B4: {=IFERROR(IF(INDEX('第1輪'!$F$2:$F$41,MATCH(A4,'第1輪'!$B$2:$B$41,0))="","",INDEX('第1輪'!$F$2:$F$41,MATCH(A4,'第1輪'!$B$2:$B$41,0))),"")} -> Pass | C4: {=IFERROR(IF(INDEX('第2輪'!$F$2:$F$41,MATCH(A4,'第2輪'!$B$2:$B$41,0))="","",INDEX('第2輪'!$F$2:$F$41,MATCH(A4,'第2輪'!$B$2:$B$41,0))),"")} -> Pass | D4: =IF(OR(B4="",C4=""),"",IF(B4=C4,1,0)) -> 1 | E4: {=IFERROR(INDEX('標準答案'!$B$2:$B$41,MATCH(A4,'標準答案'!$A$2:$A$41,0)),"")} -> Pass | F4: =IF(B4="","",IF(B4=E4,1,0)) -> 1 | G4: =IF(C4="","",IF(C4=E4,1,0)) -> 1
A5: S04 | B5: {=IFERROR(IF(INDEX('第1輪'!$F$2:$F$41,MATCH(A5,'第1輪'!$B$2:$B$41,0))="","",INDEX('第1輪'!$F$2:$F$41,MATCH(A5,'第1輪'!$B$2:$B$41,0))),"")} -> Fail | C5: {=IFERROR(IF(INDEX('第2輪'!$F$2:$F$41,MATCH(A5,'第2輪'!$B$2:$B$41,0))="","",INDEX('第2輪'!$F$2:$F$41,MATCH(A5,'第2輪'!$B$2:$B$41,0))),"")} -> Fail | D5: =IF(OR(B5="",C5=""),"",IF(B5=C5,1,0)) -> 1 | E5: {=IFERROR(INDEX('標準答案'!$B$2:$B$41,MATCH(A5,'標準答案'!$A$2:$A$41,0)),"")} -> Fail | F5: =IF(B5="","",IF(B5=E5,1,0)) -> 1 | G5: =IF(C5="","",IF(C5=E5,1,0)) -> 1
A6: S05 | B6: {=IFERROR(IF(INDEX('第1輪'!$F$2:$F$41,MATCH(A6,'第1輪'!$B$2:$B$41,0))="","",INDEX('第1輪'!$F$2:$F$41,MATCH(A6,'第1輪'!$B$2:$B$41,0))),"")} -> Pass | C6: {=IFERROR(IF(INDEX('第2輪'!$F$2:$F$41,MATCH(A6,'第2輪'!$B$2:$B$41,0))="","",INDEX('第2輪'!$F$2:$F$41,MATCH(A6,'第2輪'!$B$2:$B$41,0))),"")} -> Pass | D6: =IF(OR(B6="",C6=""),"",IF(B6=C6,1,0)) -> 1 | E6: {=IFERROR(INDEX('標準答案'!$B$2:$B$41,MATCH(A6,'標準答案'!$A$2:$A$41,0)),"")} -> Warning | F6: =IF(B6="","",IF(B6=E6,1,0)) -> 0 | G6: =IF(C6="","",IF(C6=E6,1,0)) -> 0
A7: S06 | B7: {=IFERROR(IF(INDEX('第1輪'!$F$2:$F$41,MATCH(A7,'第1輪'!$B$2:$B$41,0))="","",INDEX('第1輪'!$F$2:$F$41,MATCH(A7,'第1輪'!$B$2:$B$41,0))),"")} -> Pass | C7: {=IFERROR(IF(INDEX('第2輪'!$F$2:$F$41,MATCH(A7,'第2輪'!$B$2:$B$41,0))="","",INDEX('第2輪'!$F$2:$F$41,MATCH(A7,'第2輪'!$B$2:$B$41,0))),"")} -> Pass | D7: =IF(OR(B7="",C7=""),"",IF(B7=C7,1,0)) -> 1 | E7: {=IFERROR(INDEX('標準答案'!$B$2:$B$41,MATCH(A7,'標準答案'!$A$2:$A$41,0)),"")} -> Pass | F7: =IF(B7="","",IF(B7=E7,1,0)) -> 1 | G7: =IF(C7="","",IF(C7=E7,1,0)) -> 1
A8: S07 | B8: {=IFERROR(IF(INDEX('第1輪'!$F$2:$F$41,MATCH(A8,'第1輪'!$B$2:$B$41,0))="","",INDEX('第1輪'!$F$2:$F$41,MATCH(A8,'第1輪'!$B$2:$B$41,0))),"")} -> Pass | C8: {=IFERROR(IF(INDEX('第2輪'!$F$2:$F$41,MATCH(A8,'第2輪'!$B$2:$B$41,0))="","",INDEX('第2輪'!$F$2:$F$41,MATCH(A8,'第2輪'!$B$2:$B$41,0))),"")} -> Pass | D8: =IF(OR(B8="",C8=""),"",IF(B8=C8,1,0)) -> 1 | E8: {=IFERROR(INDEX('標準答案'!$B$2:$B$41,MATCH(A8,'標準答案'!$A$2:$A$41,0)),"")} -> Pass | F8: =IF(B8="","",IF(B8=E8,1,0)) -> 1 | G8: =IF(C8="","",IF(C8=E8,1,0)) -> 1
A9: S08 | B9: {=IFERROR(IF(INDEX('第1輪'!$F$2:$F$41,MATCH(A9,'第1輪'!$B$2:$B$41,0))="","",INDEX('第1輪'!$F$2:$F$41,MATCH(A9,'第1輪'!$B$2:$B$41,0))),"")} -> Fail | C9: {=IFERROR(IF(INDEX('第2輪'!$F$2:$F$41,MATCH(A9,'第2輪'!$B$2:$B$41,0))="","",INDEX('第2輪'!$F$2:$F$41,MATCH(A9,'第2輪'!$B$2:$B$41,0))),"")} -> Fail | D9: =IF(OR(B9="",C9=""),"",IF(B9=C9,1,0)) -> 1 | E9: {=IFERROR(INDEX('標準答案'!$B$2:$B$41,MATCH(A9,'標準答案'!$A$2:$A$41,0)),"")} -> Warning | F9: =IF(B9="","",IF(B9=E9,1,0)) -> 0 | G9: =IF(C9="","",IF(C9=E9,1,0)) -> 0
A10: S09 | B10: {=IFERROR(IF(INDEX('第1輪'!$F$2:$F$41,MATCH(A10,'第1輪'!$B$2:$B$41,0))="","",INDEX('第1輪'!$F$2:$F$41,MATCH(A10,'第1輪'!$B$2:$B$41,0))),"")} -> Pass | C10: {=IFERROR(IF(INDEX('第2輪'!$F$2:$F$41,MATCH(A10,'第2輪'!$B$2:$B$41,0))="","",INDEX('第2輪'!$F$2:$F$41,MATCH(A10,'第2輪'!$B$2:$B$41,0))),"")} -> Pass | D10: =IF(OR(B10="",C10=""),"",IF(B10=C10,1,0)) -> 1 | E10: {=IFERROR(INDEX('標準答案'!$B$2:$B$41,MATCH(A10,'標準答案'!$A$2:$A$41,0)),"")} -> Pass | F10: =IF(B10="","",IF(B10=E10,1,0)) -> 1 | G10: =IF(C10="","",IF(C10=E10,1,0)) -> 1
A11: S10 | B11: {=IFERROR(IF(INDEX('第1輪'!$F$2:$F$41,MATCH(A11,'第1輪'!$B$2:$B$41,0))="","",INDEX('第1輪'!$F$2:$F$41,MATCH(A11,'第1輪'!$B$2:$B$41,0))),"")} -> Pass | C11: {=IFERROR(IF(INDEX('第2輪'!$F$2:$F$41,MATCH(A11,'第2輪'!$B$2:$B$41,0))="","",INDEX('第2輪'!$F$2:$F$41,MATCH(A11,'第2輪'!$B$2:$B$41,0))),"")} -> Pass | D11: =IF(OR(B11="",C11=""),"",IF(B11=C11,1,0)) -> 1 | E11: {=IFERROR(INDEX('標準答案'!$B$2:$B$41,MATCH(A11,'標準答案'!$A$2:$A$41,0)),"")} -> Pass | F11: =IF(B11="","",IF(B11=E11,1,0)) -> 1 | G11: =IF(C11="","",IF(C11=E11,1,0)) -> 1
A12: S11 | B12: {=IFERROR(IF(INDEX('第1輪'!$F$2:$F$41,MATCH(A12,'第1輪'!$B$2:$B$41,0))="","",INDEX('第1輪'!$F$2:$F$41,MATCH(A12,'第1輪'!$B$2:$B$41,0))),"")} -> Pass | C12: {=IFERROR(IF(INDEX('第2輪'!$F$2:$F$41,MATCH(A12,'第2輪'!$B$2:$B$41,0))="","",INDEX('第2輪'!$F$2:$F$41,MATCH(A12,'第2輪'!$B$2:$B$41,0))),"")} -> Pass | D12: =IF(OR(B12="",C12=""),"",IF(B12=C12,1,0)) -> 1 | E12: {=IFERROR(INDEX('標準答案'!$B$2:$B$41,MATCH(A12,'標準答案'!$A$2:$A$41,0)),"")} -> Pass | F12: =IF(B12="","",IF(B12=E12,1,0)) -> 1 | G12: =IF(C12="","",IF(C12=E12,1,0)) -> 1
A13: S12 | B13: {=IFERROR(IF(INDEX('第1輪'!$F$2:$F$41,MATCH(A13,'第1輪'!$B$2:$B$41,0))="","",INDEX('第1輪'!$F$2:$F$41,MATCH(A13,'第1輪'!$B$2:$B$41,0))),"")} -> Pass | C13: {=IFERROR(IF(INDEX('第2輪'!$F$2:$F$41,MATCH(A13,'第2輪'!$B$2:$B$41,0))="","",INDEX('第2輪'!$F$2:$F$41,MATCH(A13,'第2輪'!$B$2:$B$41,0))),"")} -> Pass | D13: =IF(OR(B13="",C13=""),"",IF(B13=C13,1,0)) -> 1 | E13: {=IFERROR(INDEX('標準答案'!$B$2:$B$41,MATCH(A13,'標準答案'!$A$2:$A$41,0)),"")} -> Pass | F13: =IF(B13="","",IF(B13=E13,1,0)) -> 1 | G13: =IF(C13="","",IF(C13=E13,1,0)) -> 1
... A41: S40 | B41: {=IFERROR(IF(INDEX('第1輪'!$F$2:$F$41,MATCH(A41,'第1輪'!$B$2:$B$41,0))="","",INDEX('第1輪'!$F$2:$F$41,MATCH(A41,'第1輪'!$B$2:$B$41,0))),"")} -> Pass | C41: {=IFERROR(IF(INDEX('第2輪'!$F$2:$F$41,MATCH(A41,'第2輪'!$B$2:$B$41,0))="","",INDEX('第2輪'!$F$2:$F$41,MATCH(A41,'第2輪'!$B$2:$B$41,0))),"")} -> Warning | D41: =IF(OR(B41="",C41=""),"",IF(B41=C41,1,0)) -> 0 | E41: {=IFERROR(INDEX('標準答案'!$B$2:$B$41,MATCH(A41,'標準答案'!$A$2:$A$41,0)),"")} -> Pass | F41: =IF(B41="","",IF(B41=E41,1,0)) -> 1 | G41: =IF(C41="","",IF(C41=E41,1,0)) -> 0
A43: 兩輪皆已填的樣本數 | D43: =COUNT(D2:D41) -> 39
A44: 重複性（兩輪判定一致比例） | D44: =IF(COUNT(D2:D41)=0,"",SUM(D2:D41)/COUNT(D2:D41)) -> 0.87179487
A45: 對標準答案一致率（第1輪） | D45: =IF(COUNT(F2:F41)=0,"",SUM(F2:F41)/COUNT(F2:F41)) -> 0.69230769
A46: 對標準答案一致率（第2輪） | D46: =IF(COUNT(G2:G41)=0,"",SUM(G2:G41)/COUNT(G2:G41)) -> 0.725
A47: 漏判率（標準答案 Fail 被判 Pass，兩輪合計） | D47: =IF(COUNTIFS(E2:E41,"Fail",B2:B41,"?*")+COUNTIFS(E2:E41,"Fail",C2:C41,"?*")=0,"",(COUNTIFS(E2:E41,"Fail",B2:B41,"Pass")+COUNTIFS(E2:E41,"Fail",C2:C41,"Pass"))/(COUNTIFS(E2:E41,"Fail",B2:B41,"?*")+COUNTIFS(E2:E41,"Fail",C2:C41,"?*"))) -> 0.23529412
A48: 誤判率（標準答案 Pass 被判 Fail，兩輪合計） | D48: =IF(COUNTIFS(E2:E41,"Pass",B2:B41,"?*")+COUNTIFS(E2:E41,"Pass",C2:C41,"?*")=0,"",(COUNTIFS(E2:E41,"Pass",B2:B41,"Fail")+COUNTIFS(E2:E41,"Pass",C2:C41,"Fail"))/(COUNTIFS(E2:E41,"Pass",B2:B41,"?*")+COUNTIFS(E2:E41,"Pass",C2:C41,"?*"))) -> 0.022727273
A49: 人工複判率（判 Warning 比例，兩輪合計） | D49: =IF(COUNTIF(B2:B41,"?*")+COUNTIF(C2:C41,"?*")=0,"",(COUNTIF(B2:B41,"Warning")+COUNTIF(C2:C41,"Warning"))/(COUNTIF(B2:B41,"?*")+COUNTIF(C2:C41,"?*"))) -> 0.25316456
